<robot name="robot1" xmlns:xacro="http://www.ros.org/wiki/xacro">

  <xacro:include filename="$(find my_robot)/urdf/robot2.gazebo" />

  <link name="robot_footprint"></link>

  <joint name="robot_footprint_joint" type="fixed">
    <origin xyz="0 0 0" rpy="0 0 0" />
    <parent link="robot_footprint" />
    <child link="chassis" />
  </joint>

  <link name='chassis'>
    <pose> 0 0 0.1 0 0 0</pose>

    <inertial>
      <mass value="15.0"/>
      <origin xyz="0.0 0 0" rpy=" 0 0 0"/>
      <inertia
        ixx="0.1" ixy="0" ixz="0"
        iyy="0.1" iyz="0"
        izz="0.1"
      />
    </inertial>

    <collision name='collision'>
      <origin xyz="0 0 0" rpy=" 0 0 0"/>
      <geometry>
        <box size=".4 .2 .1"/>
      </geometry>
    </collision>

    <visual name='chassis_visual'>
      <origin xyz="0 0 0" rpy=" 0 0 0"/>
      <geometry>
        <box size=".4 .2 .1"/>
      </geometry>
    </visual>

  </link>

  <link name='lf_wheel'>

    <inertial>
      <mass value="5.0"/>
      <origin xyz="0 0 0" rpy=" 0 1.5707 1.5707"/>
      <inertia
        ixx="0.1" ixy="0" ixz="0"
        iyy="0.1" iyz="0"
        izz="0.1"
      />
    </inertial>

    <collision name='lf_wheel_collision'>
      <origin xyz="0 0 0" rpy=" 0 1.5707 1.5707"/>
      <geometry>
        <cylinder length="0.05" radius="0.1"/>
      </geometry>
    </collision>

    <visual name='lf_wheel_visual'>
      <origin xyz="0 0 0" rpy=" 0 1.5707 1.5707"/>
      <geometry>
        <cylinder length="0.05" radius="0.1"/>
      </geometry>
    </visual>

  </link>

  <joint type="continuous" name="lf_wheel_hinge">
    <origin xyz="0.15 0.15 0" rpy="0 0 0"/>
    <child link="lf_wheel"/>
    <parent link="chassis"/>
    <axis xyz="0 1 0" rpy="0 0 0"/>
    <limit effort="10000" velocity="1000"/>
    <dynamics damping="1.0" fiction="1.0"/>
    <commandTopic>cmd_vel</commandTopic>
  </joint>

  <link name='lr_wheel'>

    <inertial>
      <mass value="5.0"/>
      <origin xyz="0 0 0" rpy=" 0 1.5707 1.5707"/>
      <inertia
        ixx="0.1" ixy="0" ixz="0"
        iyy="0.1" iyz="0"
        izz="0.1"
      />
    </inertial>

    <collision name='lr_wheel_collision'>
      <origin xyz="0 0 0" rpy=" 0 1.5707 1.5707"/>
      <geometry>
        <cylinder length="0.05" radius="0.1"/>
      </geometry>
    </collision>

    <visual name='lr_wheel_visual'>
      <origin xyz="0 0 0" rpy=" 0 1.5707 1.5707"/>
      <geometry>
        <cylinder length="0.05" radius="0.1"/>
      </geometry>
    </visual>

  </link>

  <joint type="continuous" name="lr_wheel_hinge">
    <origin xyz="-0.15 0.15 0" rpy="0 0 0"/>
    <child link="lr_wheel"/>
    <parent link="chassis"/>
    <axis xyz="0 1 0" rpy="0 0 0"/>
    <limit effort="10000" velocity="1000"/>
    <dynamics damping="1.0" fiction="1.0"/>
    <commandTopic>cmd_vel</commandTopic>
  </joint>

  <link name='rf_wheel'>

    <inertial>
      <mass value="5.0"/>
      <origin xyz="0 0 0" rpy=" 0 1.5707 1.5707"/>
      <inertia
        ixx="0.1" ixy="0" ixz="0"
        iyy="0.1" iyz="0"
        izz="0.1"
      />
    </inertial>

    <collision name='rf_wheel_collision'>
      <origin xyz="0 0 0" rpy=" 0 1.5707 1.5707"/>
      <geometry>
        <cylinder length="0.05" radius="0.1"/>
      </geometry>
    </collision>

    <visual name='rf_wheel_visual'>
      <origin xyz="0 0 0" rpy=" 0 1.5707 1.5707"/>
      <geometry>
        <cylinder length="0.05" radius="0.1"/>
      </geometry>
    </visual>

  </link>

  <joint type="continuous" name="rf_wheel_hinge">
    <origin xyz="0.15 -0.15 0" rpy="0 0 0"/>
    <child link="rf_wheel"/>
    <parent link="chassis"/>
    <axis xyz="0 1 0" rpy="0 0 0"/>
    <limit effort="10000" velocity="1000"/>
    <dynamics damping="1.0" fiction="1.0"/>
    <commandTopic>cmd_vel</commandTopic>
  </joint>

  <link name='rr_wheel'>

    <inertial>
      <mass value="5.0"/>
      <origin xyz="0 0 0" rpy=" 0 1.5707 1.5707"/>
      <inertia
        ixx="0.1" ixy="0" ixz="0"
        iyy="0.1" iyz="0"
        izz="0.1"
      />
    </inertial>

    <collision name='rr_wheel_collision'>
      <origin xyz="0 0 0" rpy=" 0 1.5707 1.5707"/>
      <geometry>
        <cylinder length="0.05" radius="0.1"/>
      </geometry>
    </collision>

    <visual name='rr_wheel_visual'>
      <origin xyz="0 0 0" rpy=" 0 1.5707 1.5707"/>
      <geometry>
        <cylinder length="0.05" radius="0.1"/>
      </geometry>
    </visual>

  </link>

  <joint type="continuous" name="rr_wheel_hinge">
    <origin xyz="-0.15 -0.15 0" rpy="0 0 0"/>
    <child link="rr_wheel"/>
    <parent link="chassis"/>
    <axis xyz="0 1 0" rpy="0 0 0"/>
    <limit effort="10000" velocity="1000"/>
    <dynamics damping="1.0" fiction="1.0"/>
    <commandTopic>cmd_vel</commandTopic>
  </joint>

  <link name='camera'>

    <inertial>
      <mass value="1.0"/>
      <origin xyz="0 0 0" rpy=" 0 0 0"/>
      <box_inertia m="0.1" x="0.05" y="0.05" z="0.05"/>
      <inertia
        ixx="0.000001" ixy="0" ixz="0"
        iyy="0.000001" iyz="0"
        izz="0.000001"
      />
    </inertial>

    <collision name='camera_collision'>
      <origin xyz="0 0 0" rpy=" 0 0 0"/>
      <geometry>
        <box size="0.05 0.05 0.05"/>
      </geometry>
    </collision>

    <visual name='camera_visual'>
      <origin xyz="0 0 0" rpy=" 0 0 0"/>
      <geometry>
        <box size="0.05 0.05 0.05"/>
      </geometry>
    </visual>

    

  </link>

  <joint type="fixed" name="camera_joint">
    <origin xyz="0.2 0 0" rpy="0 0 0"/>
    <child link="camera"/>
    <parent link="chassis"/>
    <axis xyz="0 1 0"/>
    <imageTopicName>rgb/image_raw</imageTopicName>
  </joint>

  <link name='hokuyo'>

    <inertial>
      <mass value="0.00001"/>
      <origin xyz="0 0 0" rpy=" 0 0 0"/>
      <box_inertia m="0.1" x="0.05" y="0.05" z="0.05"/>
      <inertia
        ixx="0.000001" ixy="0" ixz="0"
        iyy="0.000001" iyz="0"
        izz="0.000001"
      />
    </inertial>

    <collision name='hokuyo_collision'>
      <origin xyz="0 0 0" rpy=" 0 0 0"/>
      <geometry>
        <box size="0.1 0.1 0.1"/>
      </geometry>
    </collision>

    <visual name='hokuyo_visual'>
      <origin xyz="0 0 0" rpy=" 0 0 0"/>
      <geometry>
        <mesh filename="package://my_robot/meshes/hokuyo.dae"/>
      </geometry>
    </visual>

    <topicName>/scan</topicName>

  </link>

  <joint type="fixed" name="hokuyo_joint">
    <origin xyz="0.15 0 0.1" rpy="0 0 0"/>
    <child link="hokuyo"/>
    <parent link="chassis"/>
    <axis xyz="0 1 0"/>
  </joint>

  <gazebo reference="left_wheel">
    <material>Gazebo/Green</material>
  </gazebo>

  <gazebo reference="right_wheel">
    <material>Gazebo/Green</material>
  </gazebo>

  <gazebo reference="chassis">
    <material>Gazebo/Blue</material>
  </gazebo>

  <gazebo reference="camera">
    <material>Gazebo/Red</material>
  </gazebo>



</robot>
